Workbook

Sheet Champions Sheet
A1: Agency | B1: Original Data Collection | C1: Website_Title | D1: Host Name | E1: URL Path | F1: Status | G1: GTM | H1: G-Tag | I1: State of Utah GA Account Y/N | J1: GA property Name | K1: Missing?
A2: BOPP | B2: bop.utah.gov | C2: Board of Pardons & Parole | D2: =IFERROR(__xludf.DUMMYFUNCTION("REGEXEXTRACT(E2, ""^(?:https?:\/\/)?(?:www\.)?([^\/]+)"")"),"bop.utah.gov") -> bop.utah.gov | E2: https://bop.utah.gov | F2: Active (200) | G2: GTM-T34QF72M | H2: G-4VZFST59D0 | I2: Yes | J2: BOPP - Main Website | K2: =IF(H2="", "", IF(ISNUMBER(_xlfn.XMATCH(H2, 'Viks State Rollup Sheet'!G:G)), "Found in Rollup", "MISSING in Rollup")) -> Found in Rollup
A3: CCE | B3: https://artsandmuseums.utah.gov/ | C3: Utah Division of Arts & Museums | A Division of the Department of Cultural & Community Engagement | D3: =IFERROR(__xludf.DUMMYFUNCTION("REGEXEXTRACT(E3, ""^(?:https?:\/\/)?(?:www\.)?([^\/]+)"")"),"artsandmuseums.utah.gov") -> artsandmuseums.utah.gov | E3: https://artsandmuseums.utah.gov/ | F3: Active (200) | G3: None Found | H3: G-76RDJXHW4B | I3: Yes | J3: CCE - AM | K3: =IF(H3="", "", IF(ISNUMBER(_xlfn.XMATCH(H3, 'Viks State Rollup Sheet'!G:G)), "Found in Rollup", "MISSING in Rollup")) -> Found in Rollup
A4: CCE | B4: https://indian.utah.gov/ | C4: Utah Division of Indian Affairs | A Division of the Department of Cultural & Community Engagement | D4: =IFERROR(__xludf.DUMMYFUNCTION("REGEXEXTRACT(E4, ""^(?:https?:\/\/)?(?:www\.)?([^\/]+)"")"),"indian.utah.gov") -> indian.utah.gov | E4: https://indian.utah.gov/ | F4: Active (200) | G4: None Found | H4: G-L41CPHPD25 | I4: Yes | J4: CCE - IA | K4: =IF(H4="", "", IF(ISNUMBER(_xlfn.XMATCH(H4, 'Viks State Rollup Sheet'!G:G)), "Found in Rollup", "MISSING in Rollup")) -> Found in Rollup
A5: CCE | B5: https://multicultural.utah.gov/ | C5: Utah Division Of Multicultural Affairs | A Division of the Utah Department of Cultural and Community Engagement | D5: =IFERROR(__xludf.DUMMYFUNCTION("REGEXEXTRACT(E5, ""^(?:https?:\/\/)?(?:www\.)?([^\/]+)"")"),"multicultural.utah.gov") -> multicultural.utah.gov | E5: https://multicultural.utah.gov/ | F5: Active (200) | G5: None Found | H5: G-BGQYP4L42X | I5: Yes | J5: CCE - MA | K5: =IF(H5="", "", IF(ISNUMBER(_xlfn.XMATCH(H5, 'Viks State Rollup Sheet'!G:G)), "Found in Rollup", "MISSING in Rollup")) -> Found in Rollup
A6: CCE | B6: https://community.utah.gov/ | C6: Home - CCE | D6: =IFERROR(__xludf.DUMMYFUNCTION("REGEXEXTRACT(E6, ""^(?:https?:\/\/)?(?:www\.)?([^\/]+)"")"),"community.utah.gov") -> community.utah.gov | E6: https://community.utah.gov/ | F6: Active (200) | G6: None Found | H6: G-GV5EBLNQCZ | I6: Yes | J6: CCE - Main Website | K6: =IF(H6="", "", IF(ISNUMBER(_xlfn.XMATCH(H6, 'Viks State Rollup Sheet'!G:G)), "Found in Rollup", "MISSING in Rollup")) -> Found in Rollup
A7: CCE | B7: https://community.utah.gov/psuac/ | C7: psuac - CCE | D7: =IFERROR(__xludf.DUMMYFUNCTION("REGEXEXTRACT(E7, ""^(?:https?:\/\/)?(?:www\.)?([^\/]+)"")"),"community.utah.gov") -> community.utah.gov | E7: https://community.utah.gov/psuac/ | F7: Active (200) | G7: None Found | H7: G-GV5EBLNQCZ | I7: Yes | J7: CCE - Main Website | K7: =IF(H7="", "", IF(ISNUMBER(_xlfn.XMATCH(H7, 'Viks State Rollup Sheet'!G:G)), "Found in Rollup", "MISSING in Rollup")) -> Found in Rollup
A8: CCE | B8: https://ushpo.utah.gov/ | C8: Utah State Historic Preservation Office | A Division of the Department of Cultural & Community Engagement | D8: =IFERROR(__xludf.DUMMYFUNCTION("REGEXEXTRACT(E8, ""^(?:https?:\/\/)?(?:www\.)?([^\/]+)"")"),"ushpo.utah.gov") -> ushpo.utah.gov | E8: https://ushpo.utah.gov/ | F8: Active (200) | G8: None Found | H8: G-5SDH2CY979 | I8: Yes | J8: CCE - SHPO | K8: =IF(H8="", "", IF(ISNUMBER(_xlfn.XMATCH(H8, 'Viks State Rollup Sheet'!G:G)), "Found in Rollup", "MISSING in Rollup")) -> Found in Rollup
A9: CCE | B9: https://userve.utah.gov/ | C9: UServeUtah | A Division of the Department of Cultural and Community Engagement | D9: =IFERROR(__xludf.DUMMYFUNCTION("REGEXEXTRACT(E9, ""^(?:https?:\/\/)?(?:www\.)?([^\/]+)"")"),"userve.utah.gov") -> userve.utah.gov | E9: https://userve.utah.gov/ | F9: Active (200) | G9: None Found | H9: G-1RT859T9HN | I9: Yes | J9: CCE - UServeUtah | K9: =IF(H9="", "", IF(ISNUMBER(_xlfn.XMATCH(H9, 'Viks State Rollup Sheet'!G:G)), "Found in Rollup", "MISSING in Rollup")) -> Found in Rollup
A10: CCE | B10: https://library.utah.gov/ | C10: Utah State Library Division | A Division of the Department of Cultural & Community Engagement | D10: =IFERROR(__xludf.DUMMYFUNCTION("REGEXEXTRACT(E10, ""^(?:https?:\/\/)?(?:www\.)?([^\/]+)"")"),"library.utah.gov") -> library.utah.gov | E10: https://library.utah.gov/ | F10: Active (200) | G10: None Found | H10: G-Z519DD5XXQ | I10: Yes | J10: CCE - USL | K10: =IF(H10="", "", IF(ISNUMBER(_xlfn.XMATCH(H10, 'Viks State Rollup Sheet'!G:G)), "Found in Rollup", "MISSING in Rollup")) -> Found in Rollup
A11: CCJJ | B11: https://judicialvacancy.utah.gov/ | C11: Judicial Review - Judicial Vacancy Home | D11: =IFERROR(__xludf.DUMMYFUNCTION("REGEXEXTRACT(E11, ""^(?:https?:\/\/)?(?:www\.)?([^\/]+)"")"),"judicialvacancy.utah.gov") -> judicialvacancy.utah.gov | E11: https://judicialvacancy.utah.gov/ | F11: Active (200) | G11: None Found | H11: G-PCZY0K8JQG, UA-52048446-2 | I11: Yes | J11: CCJJ - Judicial Vacancy | K11: =IF(H11="", "", IF(ISNUMBER(_xlfn.XMATCH(H11, 'Viks State Rollup Sheet'!G:G)), "Found in Rollup", "MISSING in Rollup")) -> MISSING in Rollup
A12: CCJJ | B12: https://justice.utah.gov/ | C12: Department of Criminal Justice | D12: =IFERROR(__xludf.DUMMYFUNCTION("REGEXEXTRACT(E12, ""^(?:https?:\/\/)?(?:www\.)?([^\/]+)"")"),"justice.utah.gov") -> justice.utah.gov | E12: https://justice.utah.gov/ | F12: Active (200) | G12: None Found | H12: G-9SLZ0P2YXT | I12: Yes | J12: CCJJ - Main Website | K12: =IF(H12="", "", IF(ISNUMBER(_xlfn.XMATCH(H12, 'Viks State Rollup Sheet'!G:G)), "Found in Rollup", "MISSING in Rollup")) -> Found in Rollup
A13: CCJJ | B13: https://justice.utah.gov/about-2/ | C13: #N/A | D13: =IFERROR(__xludf.DUMMYFUNCTION("REGEXEXTRACT(E13, ""^(?:https?:\/\/)?(?:www\.)?([^\/]+)"")"),"justice.utah.gov") -> justice.utah.gov | E13: https://justice.utah.gov/about-2/ | F13: Error (404) | G13: HTTP 404 | H13: G-9SLZ0P2YXT | I13: Yes | J13: CCJJ - Main Website | K13: =IF(H13="", "", IF(ISNUMBER(_xlfn.XMATCH(H13, 'Viks State Rollup Sheet'!G:G)), "Found in Rollup", "MISSING in Rollup")) -> Found in Rollup
A14: CCJJ | B14: https://justice.utah.gov/about-ccjj/extraditions/ | C14: Extraditions | Department of Criminal Justice | D14: =IFERROR(__xludf.DUMMYFUNCTION("REGEXEXTRACT(E14, ""^(?:https?:\/\/)?(?:www\.)?([^\/]+)"")"),"justice.utah.gov") -> justice.utah.gov | E14: https://justice.utah.gov/about-ccjj/extraditions/ | F14: Active (200) | G14: None Found | H14: G-9SLZ0P2YXT | I14: Yes | J14: CCJJ - Main Website | K14: =IF(H14="", "", IF(ISNUMBER(_xlfn.XMATCH(H14, 'Viks State Rollup Sheet'!G:G)), "Found in Rollup", "MISSING in Rollup")) -> Found in Rollup
A15: CCJJ | B15: https://justice.utah.gov/about-ccjj/judicial-nominating-commission/ | C15: Judicial Nominating Commission | Department of Criminal Justice | D15: =IFERROR(__xludf.DUMMYFUNCTION("REGEXEXTRACT(E15, ""^(?:https?:\/\/)?(?:www\.)?([^\/]+)"")"),"justice.utah.gov") -> justice.utah.gov | E15: https://justice.utah.gov/about-ccjj/judicial-nominating-commission/ | F15: Active (200) | G15: None Found | H15: G-9SLZ0P2YXT | I15: Yes | J15: CCJJ - Main Website | K15: =IF(H15="", "", IF(ISNUMBER(_xlfn.XMATCH(H15, 'Viks State Rollup Sheet'!G:G)), "Found in Rollup", "MISSING in Rollup")) -> Found in Rollup
A16: CCJJ | B16: https://justice.utah.gov/grants/ | C16: Grants | Department of Criminal Justice | D16: =IFERROR(__xludf.DUMMYFUNCTION("REGEXEXTRACT(E16, ""^(?:https?:\/\/)?(?:www\.)?([^\/]+)"")"),"justice.utah.gov") -> justice.utah.gov | E16: https://justice.utah.gov/grants/ | F16: Active (200) | G16: None Found | H16: G-9SLZ0P2YXT | I16: Yes | J16: CCJJ - Main Website | K16: =IF(H16="", "", IF(ISNUMBER(_xlfn.XMATCH(H16, 'Viks State Rollup Sheet'!G:G)), "Found in Rollup", "MISSING in Rollup")) -> Found in Rollup
A17: CCJJ | B17: https://justice.utah.gov/grants/federal-funding/ | C17: Federal Funding | Department of Criminal Justice | D17: =IFERROR(__xludf.DUMMYFUNCTION("REGEXEXTRACT(E17, ""^(?:https?:\/\/)?(?:www\.)?([^\/]+)"")"),"justice.utah.gov") -> justice.utah.gov | E17: https://justice.utah.gov/grants/federal-funding/ | F17: Active (200) | G17: None Found | H17: G-9SLZ0P2YXT | I17: Yes | J17: CCJJ - Main Website | K17: =IF(H17="", "", IF(ISNUMBER(_xlfn.XMATCH(H17, 'Viks State Rollup Sheet'!G:G)), "Found in Rollup", "MISSING in Rollup")) -> Found in Rollup
A18: CCJJ | B18: https://justice.utah.gov/grants/state-funding/ | C18: State Funding | Department of Criminal Justice | D18: =IFERROR(__xludf.DUMMYFUNCTION("REGEXEXTRACT(E18, ""^(?:https?:\/\/)?(?:www\.)?([^\/]+)"")"),"justice.utah.gov") -> justice.utah.gov | E18: https://justice.utah.gov/grants/state-funding/ | F18: Active (200) | G18: None Found | H18: G-9SLZ0P2YXT | I18: Yes | J18: CCJJ - Main Website | K18: =IF(H18="", "", IF(ISNUMBER(_xlfn.XMATCH(H18, 'Viks State Rollup Sheet'!G:G)), "Found in Rollup", "MISSING in Rollup")) -> Found in Rollup
A19: CCJJ | B19: https://justice.utah.gov/juvenile-justice/ | C19: #N/A | D19: =IFERROR(__xludf.DUMMYFUNCTION("REGEXEXTRACT(E19, ""^(?:https?:\/\/)?(?:www\.)?([^\/]+)"")"),"justice.utah.gov") -> justice.utah.gov | E19: https://justice.utah.gov/juvenile-justice/ | F19: Error (404) | G19: HTTP 404 | H19: G-9SLZ0P2YXT | I19: Yes | J19: CCJJ - Main Website | K19: =IF(H19="", "", IF(ISNUMBER(_xlfn.XMATCH(H19, 'Viks State Rollup Sheet'!G:G)), "Found in Rollup", "MISSING in Rollup")) -> Found in Rollup
A20: CCJJ | B20: https://justice.utah.gov/research-and-reports/ | C20: #N/A | D20: =IFERROR(__xludf.DUMMYFUNCTION("REGEXEXTRACT(E20, ""^(?:https?:\/\/)?(?:www\.)?([^\/]+)"")"),"justice.utah.gov") -> justice.utah.gov | E20: https://justice.utah.gov/research-and-reports/ | F20: Error (404) | G20: HTTP 404 | H20: G-9SLZ0P2YXT | I20: Yes | J20: CCJJ - Main Website | K20: =IF(H20="", "", IF(ISNUMBER(_xlfn.XMATCH(H20, 'Viks State Rollup Sheet'!G:G)), "Found in Rollup", "MISSING in Rollup")) -> Found in Rollup
A21: CCJJ | B21: https://justice.utah.gov/sentencing/ | C21: #N/A | D21: =IFERROR(__xludf.DUMMYFUNCTION("REGEXEXTRACT(E21, ""^(?:https?:\/\/)?(?:www\.)?([^\/]+)"")"),"justice.utah.gov") -> justice.utah.gov | E21: https://justice.utah.gov/sentencing/ | F21: Error (404) | G21: HTTP 404 | H21: G-9SLZ0P2YXT | I21: Yes | J21: CCJJ - Main Website | K21: =IF(H21="", "", IF(ISNUMBER(_xlfn.XMATCH(H21, 'Viks State Rollup Sheet'!G:G)), "Found in Rollup", "MISSING in Rollup")) -> Found in Rollup
A22: CCJJ | B22: https://justice.utah.gov/sentencing/eforms/ | C22: eForms | Department of Criminal Justice | D22: =IFERROR(__xludf.DUMMYFUNCTION("REGEXEXTRACT(E22, ""^(?:https?:\/\/)?(?:www\.)?([^\/]+)"")"),"justice.utah.gov") -> justice.utah.gov | E22: https://justice.utah.gov/sentencing/eforms/ | F22: Active (200) | G22: None Found | H22: G-9SLZ0P2YXT | I22: Yes | J22: CCJJ - Main Website | K22: =IF(H22="", "", IF(ISNUMBER(_xlfn.XMATCH(H22, 'Viks State Rollup Sheet'!G:G)), "Found in Rollup", "MISSING in Rollup")) -> Found in Rollup
A23: CCJJ | B23: https://justice.utah.gov/sentencing/sentencing-and-release-guidelines/ | C23: #N/A | D23: =IFERROR(__xludf.DUMMYFUNCTION("REGEXEXTRACT(E23, ""^(?:https?:\/\/)?(?:www\.)?([^\/]+)"")"),"justice.utah.gov") -> justice.utah.gov | E23: https://justice.utah.gov/sentencing/sentencing-and-release-guidelines/ | F23: Error (404) | G23: HTTP 404 | H23: G-9SLZ0P2YXT | I23: Yes | J23: CCJJ - Main Website | K23: =IF(H23="", "", IF(ISNUMBER(_xlfn.XMATCH(H23, 'Viks State Rollup Sheet'!G:G)), "Found in Rollup", "MISSING in Rollup")) -> Found in Rollup
A24: CCJJ | B24: https://crimevictim.utah.gov/grants/grant-solicitations/ | C24: #N/A | D24: =IFERROR(__xludf.DUMMYFUNCTION("REGEXEXTRACT(E24, ""^(?:https?:\/\/)?(?:www\.)?([^\/]+)"")"),"crimevictim.utah.gov") -> crimevictim.utah.gov | E24: https://crimevictim.utah.gov/grants/grant-solicitations/ | F24: Error (404) | G24: HTTP 404 | H24: G-2NQRP84TH7 | I24: Yes | J24: CCJJ - UOVC | K24: =IF(H24="", "", IF(ISNUMBER(_xlfn.XMATCH(H24, 'Viks State Rollup Sheet'!G:G)), "Found in Rollup", "MISSING in Rollup")) -> Found in Rollup
A25: CCJJ | B25: https://crimevictim.utah.gov/victim-financial-assistance/application-process/ | C25: #N/A | D25: =IFERROR(__xludf.DUMMYFUNCTION("REGEXEXTRACT(E25, ""^(?:https?:\/\/)?(?:www\.)?([^\/]+)"")"),"crimevictim.utah.gov") -> crimevictim.utah.gov | E25: https://crimevictim.utah.gov/victim-financial-assistance/application-process/ | F25: Error (404) | G25: HTTP 404 | H25: G-2NQRP84TH7 | I25: Yes | J25: CCJJ - UOVC | K25: =IF(H25="", "", IF(ISNUMBER(_xlfn.XMATCH(H25, 'Viks State Rollup Sheet'!G:G)), "Found in Rollup", "MISSING in Rollup")) -> Found in Rollup
A26: CCJJ | B26: https://crimevictim.utah.gov/victim-rights/ | C26: #N/A | D26: =IFERROR(__xludf.DUMMYFUNCTION("REGEXEXTRACT(E26, ""^(?:https?:\/\/)?(?:www\.)?([^\/]+)"")"),"crimevictim.utah.gov") -> crimevictim.utah.gov | E26: https://crimevictim.utah.gov/victim-rights/ | F26: Error (404) | G26: HTTP 404 | H26: G-2NQRP84TH7 | I26: Yes | J26: CCJJ - UOVC | K26: =IF(H26="", "", IF(ISNUMBER(_xlfn.XMATCH(H26, 'Viks State Rollup Sheet'!G:G)), "Found in Rollup", "MISSING in Rollup")) -> Found in Rollup
A27: DABS | B27: abs.utah.gov | C27: Utah DABS - Utah DABS | D27: =IFERROR(__xludf.DUMMYFUNCTION("REGEXEXTRACT(E27, ""^(?:https?:\/\/)?(?:www\.)?([^\/]+)"")"),"abs.utah.gov") -> abs.utah.gov | E27: https://abs.utah.gov | F27: Active (200) | G27: GTM-5DQJR6SM | H27: G-X5QN659TK4 | I27: Yes | J27: DABS - Main Website | K27: =IF(H27="", "", IF(ISNUMBER(_xlfn.XMATCH(H27, 'Viks State Rollup Sheet'!G:G)), "Found in Rollup", "MISSING in Rollup")) -> Found in Rollup
A28: DABS | B28: Licensee Ordering Portal | C28: Licensee Ordering Portal | D28: =IFERROR(__xludf.DUMMYFUNCTION("REGEXEXTRACT(E28, ""^(?:https?:\/\/)?(?:www\.)?([^\/]+)"")"),"abs.utah.gov") -> abs.utah.gov | E28: https://abs.utah.gov/licenses-permits/licensee-orders/ | F28: No Original Link | G28: GTM-5DQJR6SM | H28: G-X5QN659TK4 | I28: Yes | J28: DABS - Main Website | K28: =IF(H28="", "", IF(ISNUMBER(_xlfn.XMATCH(H28, 'Viks State Rollup Sheet'!G:G)), "Found in Rollup", "MISSING in Rollup")) -> Found in Rollup
A29: DABS | B29: Licensing and Permitting System | C29: Licensing and Permitting System | D29: =IFERROR(__xludf.DUMMYFUNCTION("REGEXEXTRACT(E29, ""^(?:https?:\/\/)?(?:www\.)?([^\/]+)"")"),"abs.utah.gov") -> abs.utah.gov | E29: https://abs.utah.gov/licenses-permits/licensing-system/ | F29: No Original Link | G29: GTM-5DQJR6SM | H29: G-X5QN659TK4 | I29: Yes | J29: DABS - Main Website | K29: =IF(H29="", "", IF(ISNUMBER(_xlfn.XMATCH(H29, 'Viks State Rollup Sheet'!G:G)), "Found in Rollup", "MISSING in Rollup")) -> Found in Rollup
A30: DABS | B30: Learning Portal (SABA) | C30: Learning Portal (SABA) | D30: =IFERROR(__xludf.DUMMYFUNCTION("REGEXEXTRACT(E30, ""^(?:https?:\/\/)?(?:www\.)?([^\/]+)"")"),"abs.utah.gov") -> abs.utah.gov | E30: https://abs.utah.gov/licenses-permits/training/ | F30: No Original Link | G30: GTM-5DQJR6SM | H30: G-X5QN659TK4 | I30: Yes | J30: DABS - Main Website | K30: =IF(H30="", "", IF(ISNUMBER(_xlfn.XMATCH(H30, 'Viks State Rollup Sheet'!G:G)), "Found in Rollup", "MISSING in Rollup")) -> Found in Rollup
A31: DABS | B31: Special Ordering Portal | C31: Special Ordering Portal | D31: =IFERROR(__xludf.DUMMYFUNCTION("REGEXEXTRACT(E31, ""^(?:https?:\/\/)?(?:www\.)?([^\/]+)"")"),"abs.utah.gov") -> abs.utah.gov | E31: https://abs.utah.gov/shop-products/special-orders/ | F31: No Original Link | G31: GTM-5DQJR6SM | H31: G-X5QN659TK4 | I31: Yes | J31: DABS - Main Website | K31: =IF(H31="", "", IF(ISNUMBER(_xlfn.XMATCH(H31, 'Viks State Rollup Sheet'!G:G)), "Found in Rollup", "MISSING in Rollup")) -> Found in Rollup
A32: DABS | B32: Vendor Portal | C32: Vendor Portal | D32: =IFERROR(__xludf.DUMMYFUNCTION("REGEXEXTRACT(E32, ""^(?:https?:\/\/)?(?:www\.)?([^\/]+)"")"),"abs.utah.gov") -> abs.utah.gov | E32: https://abs.utah.gov/vendors/vendor-portal/ | F32: No Original Link | G32: GTM-5DQJR6SM | H32: G-X5QN659TK4 | I32: Yes | J32: DABS - Main Website | K32: =IF(H32="", "", IF(ISNUMBER(_xlfn.XMATCH(H32, 'Viks State Rollup Sheet'!G:G)), "Found in Rollup", "MISSING in Rollup")) -> Found in Rollup
A33: DABS | B33: Product Locator | C33: Product Locator | D33: =IFERROR(__xludf.DUMMYFUNCTION("REGEXEXTRACT(E33, ""^(?:https?:\/\/)?(?:www\.)?([^\/]+)"")"),"webapps2.abc.utah.gov") -> webapps2.abc.utah.gov | E33: https://webapps2.abc.utah.gov/ProdApps/ProductLocatorCore | F33: No Original Link | G33: None Found | H33: G-X5QN659TK4 | I33: Yes | J33: DABS - Main Website | K33: =IF(H33="", "", IF(ISNUMBER(_xlfn.XMATCH(H33, 'Viks State Rollup Sheet'!G:G)), "Found in Rollup", "MISSING in Rollup")) -> Found in Rollup
A34: DABS | B34: Rare and High Demand Products Portal | C34: Rare and High Demand Products Portal | D34: =IFERROR(__xludf.DUMMYFUNCTION("REGEXEXTRACT(E34, ""^(?:https?:\/\/)?(?:www\.)?([^\/]+)"")"),"webapps2.abc.utah.gov") -> webapps2.abc.utah.gov | E34: https://webapps2.abc.utah.gov/ProdApps/RareHighDemandProducts | F34: No Original Link | G34: None Found | H34: G-X5QN659TK4 | I34: Yes | J34: DABS - Main Website | K34: =IF(H34="", "", IF(ISNUMBER(_xlfn.XMATCH(H34, 'Viks State Rollup Sheet'!G:G)), "Found in Rollup", "MISSING in Rollup")) -> Found in Rollup
A35: DEQ | B35: Large Animal Feeding Operations | C35: Large Animal Feeding Operations | D35: =IFERROR(__xludf.DUMMYFUNCTION("REGEXEXTRACT(E35, ""^(?:https?:\/\/)?(?:www\.)?([^\/]+)"")"),"ag.utah.gov") -> ag.utah.gov | E35: https://ag.utah.gov/conservation/animal-feeding-operations/ | F35: No Original Link | G35: None Found | H35: G-X8DRQJS2B4 | I35: Yes | J35: DAF - Main Website | K35: =IF(H35="", "", IF(ISNUMBER(_xlfn.XMATCH(H35, 'Viks State Rollup Sheet'!G:G)), "Found in Rollup", "MISSING in Rollup")) -> Found in Rollup
A36: UDAF | B36: https://ag.utah.gov/industrialhempprogram/ | C36: Industrial Hemp | Utah Department of Agriculture and Food | D36: =IFERROR(__xludf.DUMMYFUNCTION("REGEXEXTRACT(E36, ""^(?:https?:\/\/)?(?:www\.)?([^\/]+)"")"),"ag.utah.gov") -> ag.utah.gov | E36: https://ag.utah.gov/industrialhempprogram/ | F36: Active (200) | G36: None Found | H36: G-X8DRQJS2B4 | I36: Yes | J36: DAF - Main Website | K36: =IF(H36="", "", IF(ISNUMBER(_xlfn.XMATCH(H36, 'Viks State Rollup Sheet'!G:G)), "Found in Rollup", "MISSING in Rollup")) -> Found in Rollup
A37: UDAF | B37: urrt.utah.gov | C37: Utah Rapid Response Team | D37: =IFERROR(__xludf.DUMMYFUNCTION("REGEXEXTRACT(E37, ""^(?:https?:\/\/)?(?:www\.)?([^\/]+)"")"),"urrt.utah.gov") -> urrt.utah.gov | E37: https://urrt.utah.gov | F37: Active (200) | G37: None Found | H37: G-9B2BJX00ML | I37: Yes | J37: DAF - Rapid Response Team | K37: =IF(H37="", "", IF(ISNUMBER(_xlfn.XMATCH(H37, 'Viks State Rollup Sheet'!G:G)), "Found in Rollup", "MISSING in Rollup")) -> Found in Rollup
A38: DEQ | B38: daqpermitting.utah.gov | C38: Air Quality Permitting Notices - Utah Department of Environmental Quality | D38: =IFERROR(__xludf.DUMMYFUNCTION("REGEXEXTRACT(E38, ""^(?:https?:\/\/)?(?:www\.)?([^\/]+)"")"),"daqpermitting.utah.gov") -> daqpermitting.utah.gov | E38: https://daqpermitting.utah.gov | F38: Active (200) | G38: GTM-54M499X | H38: G-0HM105CNL9 | I38: Yes | J38: DEQ - DAQ - Permitting App | K38: =IF(H38="", "", IF(ISNUMBER(_xlfn.XMATCH(H38, 'Viks State Rollup Sheet'!G:G)), "Found in Rollup", "MISSING in Rollup")) -> Found in Rollup
A39: DEQ | B39: deq.utah.gov | C39: Home - Utah Department of Environmental Quality | D39: =IFERROR(__xludf.DUMMYFUNCTION("REGEXEXTRACT(E39, ""^(?:https?:\/\/)?(?:www\.)?([^\/]+)"")"),"deq.utah.gov") -> deq.utah.gov | E39: https://deq.utah.gov | F39: Active (200) | G39: GTM-P5KCN7V | H39: G-RRTEGT2P5N | I39: Yes | J39: DEQ - Main Website | K39: =IF(H39="", "", IF(ISNUMBER(_xlfn.XMATCH(H39, 'Viks State Rollup Sheet'!G:G)), "Found in Rollup", "MISSING in Rollup")) -> Found in Rollup
A40: DEQ | B40: Air Quality Complaint Form | C40: Air Quality Complaint Form | D40: =IFERROR(__xludf.DUMMYFUNCTION("REGEXEXTRACT(E40, ""^(?:https?:\/\/)?(?:www\.)?([^\/]+)"")"),"deq.utah.gov") -> deq.utah.gov | E40: https://deq.utah.gov/daq/air-quality-complaint-form | F40: No Original Link | G40: GTM-P5KCN7V | H40: G-RRTEGT2P5N | I40: Yes | J40: DEQ - Main Website | K40: =IF(H40="", "", IF(ISNUMBER(_xlfn.XMATCH(H40, 'Viks State Rollup Sheet'!G:G)), "Found in Rollup", "MISSING in Rollup")) -> Found in Rollup
...

Sheet Sheet12

Sheet State Google Tags on Account
A1: GA360_Property_Name | B1: GA360_Property_ID | C1: Stream_Name | D1: Stream_URL | E1: Measurement_ID | F1: Missing
A2: DGO - DHRM - Offer Acceptance | B2: 254102168 | C2: Offer Acceptance | D2: https://offeracceptance.utah.gov/ | E2: G-SHRVL5TZ37 | F2: =IF(E2="", "", IF(ISNUMBER(_xlfn.XMATCH(E2, 'Champions Sheet'!H:H)), "Found in Master", "MISSING in Alicia's")) -> MISSING in Alicia's
A3: DOC - DOPL - UPHP | B3: 255775667 | C3: UPHP website | D3: https://uphp.utah.gov/ | E3: G-RTV6KNP85X | F3: =IF(E3="", "", IF(ISNUMBER(_xlfn.XMATCH(E3, 'Champions Sheet'!H:H)), "Found in Master", "MISSING in Alicia's")) -> MISSING in Alicia's
A4: CCE - AM - Museum Social Impact | B4: 258064736 | C4: Museum Social Impact Website | D4: https://museumsocialimpact.org | E4: G-4ERD645EY8 | F4: =IF(E4="", "", IF(ISNUMBER(_xlfn.XMATCH(E4, 'Champions Sheet'!H:H)), "Found in Master", "MISSING in Alicia's")) -> MISSING in Alicia's
A5: UDOT - Trucksmart - trucksmart.udot.utah.gov | B5: 263913003 | C5: Trucksmart 2021 | D5: https://trucksmart.udot.utah.gov | E5: G-JM4TGYJ7Y3 | F5: =IF(E5="", "", IF(ISNUMBER(_xlfn.XMATCH(E5, 'Champions Sheet'!H:H)), "Found in Master", "MISSING in Alicia's")) -> MISSING in Alicia's
A6: UDOT - Zero Fatalities - zerofatalities.com | B6: 268026917 | C6: Zero Fatalities - GA4 | D6: https://zerofatalities.com | E6: G-W74DBWG5TL | F6: =IF(E6="", "", IF(ISNUMBER(_xlfn.XMATCH(E6, 'Champions Sheet'!H:H)), "Found in Master", "MISSING in Alicia's")) -> MISSING in Alicia's
A7: DEQ - Main Website | B7: 270736262 | C7: deq.utah.gov - GA4 | D7: https://deq.utah.gov | E7: G-RRTEGT2P5N | F7: =IF(E7="", "", IF(ISNUMBER(_xlfn.XMATCH(E7, 'Champions Sheet'!H:H)), "Found in Master", "MISSING in Alicia's")) -> Found in Master
A8: DEQ - DAQ - Monitoring App | B8: 271285752 | C8: AQ Monitoring - GA4 | D8: https://air.utah.gov | E8: G-YTMMRM6RBF | F8: =IF(E8="", "", IF(ISNUMBER(_xlfn.XMATCH(E8, 'Champions Sheet'!H:H)), "Found in Master", "MISSING in Alicia's")) -> MISSING in Alicia's
A9: CCE - Intranet | B9: 272286753 | C9: CCE - Intranet | D9: https://cceintranet.utah.gov | E9: G-6HVSGMMQCC | F9: =IF(E9="", "", IF(ISNUMBER(_xlfn.XMATCH(E9, 'Champions Sheet'!H:H)), "Found in Master", "MISSING in Alicia's")) -> MISSING in Alicia's
A10: CCE - Main Website | B10: 272291754 | C10: CCE - Community | D10: https://community.utah.gov | E10: G-GV5EBLNQCZ | F10: =IF(E10="", "", IF(ISNUMBER(_xlfn.XMATCH(E10, 'Champions Sheet'!H:H)), "Found in Master", "MISSING in Alicia's")) -> Found in Master
A11: DEQ - DAQ - Permitting App | B11: 272372086 | C11: AQ Permitting - GA4 | D11: https://daqpermitting.utah.gov | E11: G-0HM105CNL9 | F11: =IF(E11="", "", IF(ISNUMBER(_xlfn.XMATCH(E11, 'Champions Sheet'!H:H)), "Found in Master", "MISSING in Alicia's")) -> Found in Master
A12: DOC - Administration | B12: 277811441 | C12: Commerce Administration | D12: https://admin.commerce.utah.gov | E12: G-XTZ95C217Z | F12: =IF(E12="", "", IF(ISNUMBER(_xlfn.XMATCH(E12, 'Champions Sheet'!H:H)), "Found in Master", "MISSING in Alicia's")) -> MISSING in Alicia's
A13: DOC - Blog | B13: 279127117 | C13: Commerce Blog | D13: https://blog.commerce.utah.gov | E13: G-E6HM2EH098 | F13: =IF(E13="", "", IF(ISNUMBER(_xlfn.XMATCH(E13, 'Champions Sheet'!H:H)), "Found in Master", "MISSING in Alicia's")) -> MISSING in Alicia's
... A296: DXP - Test Website - design-system-sandbox.utah.gov | B296: 549457251 | C296: DXP - Test Website - design-system-sandbox.utah.gov/ | D296: https://design-system-sandbox.utah.gov | E296: G-BW1SYM40YP | F296: =IF(E296="", "", IF(ISNUMBER(_xlfn.XMATCH(E296, 'Champions Sheet'!H:H)), "Found in Master", "MISSING in Alicia's")) -> MISSING in Alicia's

Sheet Viks State Rollup Sheet
A1: Account ID | B1: Roll-up Property ID | C1: Roll-up Property Name | D1: Source Property ID | E1: Source Property Name | F1: Source Stream URL(s) | G1: Source Tag ID(s) | H1: In Master Sheet? | I1: Missing in My State API Pull
A2: 295896210 | B2: 488601532 | C2: State of Utah Aggregate - Low Traffic | D2: 346064368 | E2: Attorney General | F2: http://attorneygeneral.utah.gov | G2: G-SF9EQBX4K6 | H2: =IF(G2="", "", IF(ISNUMBER(_xlfn.XMATCH(G2, 'Champions Sheet'!H:H)), "Found in Master", "MISSING in Alicia's")) -> MISSING in Alicia's | I2: =IF(G2="", "", IF(ISNUMBER(_xlfn.XMATCH(G2, 'State Google Tags on Account'!E:E)), "Found in Alicia API Pull", "MISSING in Alicia's API Pull")) -> Found in Alicia API Pull
A3: 295896210 | B3: 450964503 | C3: State of Utah Aggregate | D3: 381643798 | E3: Office of the Utah State Auditor | F3: http://auditor.utah.gov | G3: G-YBQJ163BW5 | H3: =IF(G3="", "", IF(ISNUMBER(_xlfn.XMATCH(G3, 'Champions Sheet'!H:H)), "Found in Master", "MISSING in Alicia's")) -> MISSING in Alicia's | I3: =IF(G3="", "", IF(ISNUMBER(_xlfn.XMATCH(G3, 'State Google Tags on Account'!E:E)), "Found in Alicia API Pull", "MISSING in Alicia's API Pull")) -> Found in Alicia API Pull
A4: 295896210 | B4: 487084052 | C4: DOC - All Public Websites | D4: 331553278 | E4: DOC - All Websites - commerce.utah.gov | F4: http://commerce.utah.gov | G4: G-PZZ62EM49P | H4: =IF(G4="", "", IF(ISNUMBER(_xlfn.XMATCH(G4, 'Champions Sheet'!H:H)), "Found in Master", "MISSING in Alicia's")) -> MISSING in Alicia's | I4: =IF(G4="", "", IF(ISNUMBER(_xlfn.XMATCH(G4, 'State Google Tags on Account'!E:E)), "Found in Alicia API Pull", "MISSING in Alicia's API Pull")) -> Found in Alicia API Pull
A5: 295896210 | B5: 450964503 | C5: State of Utah Aggregate | D5: 331553278 | E5: DOC - All Websites - commerce.utah.gov | F5: http://commerce.utah.gov | G5: G-PZZ62EM49P | H5: =IF(G5="", "", IF(ISNUMBER(_xlfn.XMATCH(G5, 'Champions Sheet'!H:H)), "Found in Master", "MISSING in Alicia's")) -> MISSING in Alicia's | I5: =IF(G5="", "", IF(ISNUMBER(_xlfn.XMATCH(G5, 'State Google Tags on Account'!E:E)), "Found in Alicia API Pull", "MISSING in Alicia's API Pull")) -> Found in Alicia API Pull
A6: 295896210 | B6: 487084052 | C6: DOC - All Public Websites | D6: 331579917 | E6: DOC - CORP | F6: http://corporations.utah.gov | G6: G-RED8SLHVQ3 | H6: =IF(G6="", "", IF(ISNUMBER(_xlfn.XMATCH(G6, 'Champions Sheet'!H:H)), "Found in Master", "MISSING in Alicia's")) -> MISSING in Alicia's | I6: =IF(G6="", "", IF(ISNUMBER(_xlfn.XMATCH(G6, 'State Google Tags on Account'!E:E)), "Found in Alicia API Pull", "MISSING in Alicia's API Pull")) -> Found in Alicia API Pull
A7: 295896210 | B7: 450964503 | C7: State of Utah Aggregate | D7: 331579917 | E7: DOC - CORP | F7: http://corporations.utah.gov | G7: G-RED8SLHVQ3 | H7: =IF(G7="", "", IF(ISNUMBER(_xlfn.XMATCH(G7, 'Champions Sheet'!H:H)), "Found in Master", "MISSING in Alicia's")) -> MISSING in Alicia's | I7: =IF(G7="", "", IF(ISNUMBER(_xlfn.XMATCH(G7, 'State Google Tags on Account'!E:E)), "Found in Alicia API Pull", "MISSING in Alicia's API Pull")) -> Found in Alicia API Pull
A8: 295896210 | B8: 488601532 | C8: State of Utah Aggregate - Low Traffic | D8: 346115405 | E8: CCJJ - UOVC | F8: http://crimevictim.utah.gov/ | G8: G-2NQRP84TH7 | H8: =IF(G8="", "", IF(ISNUMBER(_xlfn.XMATCH(G8, 'Champions Sheet'!H:H)), "Found in Master", "MISSING in Alicia's")) -> Found in Master | I8: =IF(G8="", "", IF(ISNUMBER(_xlfn.XMATCH(G8, 'State Google Tags on Account'!E:E)), "Found in Alicia API Pull", "MISSING in Alicia's API Pull")) -> Found in Alicia API Pull
A9: 295896210 | B9: 487084052 | C9: DOC - All Public Websites | D9: 331609147 | E9: DOC - DCP, OCS, DRE | F9: http://dcp.utah.gov/ | G9: G-CVR3K81XQZ | H9: =IF(G9="", "", IF(ISNUMBER(_xlfn.XMATCH(G9, 'Champions Sheet'!H:H)), "Found in Master", "MISSING in Alicia's")) -> MISSING in Alicia's | I9: =IF(G9="", "", IF(ISNUMBER(_xlfn.XMATCH(G9, 'State Google Tags on Account'!E:E)), "Found in Alicia API Pull", "MISSING in Alicia's API Pull")) -> Found in Alicia API Pull
A10: 295896210 | B10: 450964503 | C10: State of Utah Aggregate | D10: 331609147 | E10: DOC - DCP, OCS, DRE | F10: http://dcp.utah.gov/ | G10: G-CVR3K81XQZ | H10: =IF(G10="", "", IF(ISNUMBER(_xlfn.XMATCH(G10, 'Champions Sheet'!H:H)), "Found in Master", "MISSING in Alicia's")) -> MISSING in Alicia's | I10: =IF(G10="", "", IF(ISNUMBER(_xlfn.XMATCH(G10, 'State Google Tags on Account'!E:E)), "Found in Alicia API Pull", "MISSING in Alicia's API Pull")) -> Found in Alicia API Pull
A11: 295896210 | B11: 450964503 | C11: State of Utah Aggregate | D11: 385127374 | E11: LG - Elections - Disclosures | F11: http://disclosures.utah.gov | G11: G-3BSQB369FR | H11: =IF(G11="", "", IF(ISNUMBER(_xlfn.XMATCH(G11, 'Champions Sheet'!H:H)), "Found in Master", "MISSING in Alicia's")) -> MISSING in Alicia's | I11: =IF(G11="", "", IF(ISNUMBER(_xlfn.XMATCH(G11, 'State Google Tags on Account'!E:E)), "Found in Alicia API Pull", "MISSING in Alicia's API Pull")) -> Found in Alicia API Pull
A12: 295896210 | B12: 482352716 | C12: DHHS - Roll-up - All properties | D12: 346275491 | E12: DHHS - DLBC - dlbc.utah.gov | F12: http://dlbc.utah.gov | G12: G-Z8E586EN9V | H12: =IF(G12="", "", IF(ISNUMBER(_xlfn.XMATCH(G12, 'Champions Sheet'!H:H)), "Found in Master", "MISSING in Alicia's")) -> MISSING in Alicia's | I12: =IF(G12="", "", IF(ISNUMBER(_xlfn.XMATCH(G12, 'State Google Tags on Account'!E:E)), "Found in Alicia API Pull", "MISSING in Alicia's API Pull")) -> Found in Alicia API Pull
A13: 295896210 | B13: 450964503 | C13: State of Utah Aggregate | D13: 346275491 | E13: DHHS - DLBC - dlbc.utah.gov | F13: http://dlbc.utah.gov | G13: G-Z8E586EN9V | H13: =IF(G13="", "", IF(ISNUMBER(_xlfn.XMATCH(G13, 'Champions Sheet'!H:H)), "Found in Master", "MISSING in Alicia's")) -> MISSING in Alicia's | I13: =IF(G13="", "", IF(ISNUMBER(_xlfn.XMATCH(G13, 'State Google Tags on Account'!E:E)), "Found in Alicia API Pull", "MISSING in Alicia's API Pull")) -> Found in Alicia API Pull
... A19: 295896210 | B19: 450964503 | C19: State of Utah Aggregate | D19: 346745177 | E19: DHHS - DSPD - dspd.utah.gov | F19: http://dspd.utah.gov | G19: G-E5MRG90E2V | H19: =IF(G19="", "", IF(ISNUMBER(_xlfn.XMATCH(G19, 'Champions Sheet'!H:H)), "Found in Master", "MISSING in Alicia's")) -> Found in Master | I19: =IF(G19="", "", IF(ISNUMBER(_xlfn.XMATCH(G19, 'State Google Tags on Account'!E:E)), "Found in Alicia API Pull", "MISSING in Alicia's API Pull")) -> Found in Alicia API Pull
A20: 295896210 | B20: 482151148 | C20: DNR - All Websites | D20: 324057916 | E20: DNR - DWR - Recreation access | F20: http://dwrapps.utah.gov/ram/start2, https://dwrapps.utah.gov/events | G20: G-11Y80DXQRJ, G-0GSTKZMBKS | H20: =IF(G20="", "", IF(ISNUMBER(_xlfn.XMATCH(G20, 'Champions Sheet'!H:H)), "Found in Master", "MISSING in Alicia's")) -> MISSING in Alicia's | I20: Manually found only G-0GSTKZMBKS
A21: 295896210 | B21: 450964503 | C21: State of Utah Aggregate | D21: 324057916 | E21: DNR - DWR - Recreation access | F21: http://dwrapps.utah.gov/ram/start2, https://dwrapps.utah.gov/events | G21: G-11Y80DXQRJ, G-0GSTKZMBKS | H21: =IF(G21="", "", IF(ISNUMBER(_xlfn.XMATCH(G21, 'Champions Sheet'!H:H)), "Found in Master", "MISSING in Alicia's")) -> MISSING in Alicia's | I21: Manually found only G-0GSTKZMBKS
A22: 295896210 | B22: 482151148 | C22: DNR - All Websites | D22: 331548960 | E22: DNR - WRe - Opendata | F22: http://dwre-utahdnr.opendata.arcgis.com/ | G22: G-HTG1PCPGHN | H22: =IF(G22="", "", IF(ISNUMBER(_xlfn.XMATCH(G22, 'Champions Sheet'!H:H)), "Found in Master", "MISSING in Alicia's")) -> MISSING in Alicia's | I22: =IF(G22="", "", IF(ISNUMBER(_xlfn.XMATCH(G22, 'State Google Tags on Account'!E:E)), "Found in Alicia API Pull", "MISSING in Alicia's API Pull")) -> Found in Alicia API Pull
A23: 295896210 | B23: 450964503 | C23: State of Utah Aggregate | D23: 331548960 | E23: DNR - WRe - Opendata | F23: http://dwre-utahdnr.opendata.arcgis.com/ | G23: G-HTG1PCPGHN | H23: =IF(G23="", "", IF(ISNUMBER(_xlfn.XMATCH(G23, 'Champions Sheet'!H:H)), "Found in Master", "MISSING in Alicia's")) -> MISSING in Alicia's | I23: =IF(G23="", "", IF(ISNUMBER(_xlfn.XMATCH(G23, 'State Google Tags on Account'!E:E)), "Found in Alicia API Pull", "MISSING in Alicia's API Pull")) -> Found in Alicia API Pull
A24: 295896210 | B24: 450964503 | C24: State of Utah Aggregate | D24: 362376887 | E24: LG - Election Results | F24: http://electionresults.utah.gov/ | G24: G-MJKWT53WEH | H24: =IF(G24="", "", IF(ISNUMBER(_xlfn.XMATCH(G24, 'Champions Sheet'!H:H)), "Found in Master", "MISSING in Alicia's")) -> MISSING in Alicia's | I24: =IF(G24="", "", IF(ISNUMBER(_xlfn.XMATCH(G24, 'State Google Tags on Account'!E:E)), "Found in Alicia API Pull", "MISSING in Alicia's API Pull")) -> Found in Alicia API Pull
A25: 295896210 | B25: 487657823 | C25: DPS - All Websites | D25: 362601737 | E25: DPS - EMS | F25: http://ems.utah.gov | G25: G-QT6PQS2CRD | H25: =IF(G25="", "", IF(ISNUMBER(_xlfn.XMATCH(G25, 'Champions Sheet'!H:H)), "Found in Master", "MISSING in Alicia's")) -> MISSING in Alicia's | I25: =IF(G25="", "", IF(ISNUMBER(_xlfn.XMATCH(G25, 'State Google Tags on Account'!E:E)), "Found in Alicia API Pull", "MISSING in Alicia's API Pull")) -> Found in Alicia API Pull
A26: 295896210 | B26: 450964503 | C26: State of Utah Aggregate | D26: 362601737 | E26: DPS - EMS | F26: http://ems.utah.gov | G26: G-QT6PQS2CRD | H26: =IF(G26="", "", IF(ISNUMBER(_xlfn.XMATCH(G26, 'Champions Sheet'!H:H)), "Found in Master", "MISSING in Alicia's")) -> MISSING in Alicia's | I26: =IF(G26="", "", IF(ISNUMBER(_xlfn.XMATCH(G26, 'State Google Tags on Account'!E:E)), "Found in Alicia API Pull", "MISSING in Alicia's API Pull")) -> Found in Alicia API Pull
A27: 295896210 | B27: 482151148 | C27: DNR - All Websites | D27: 346726586 | E27: DNR - OED | F27: http://energy.utah.gov | G27: G-8F73JSYN4N | H27: =IF(G27="", "", IF(ISNUMBER(_xlfn.XMATCH(G27, 'Champions Sheet'!H:H)), "Found in Master", "MISSING in Alicia's")) -> Found in Master | I27: =IF(G27="", "", IF(ISNUMBER(_xlfn.XMATCH(G27, 'State Google Tags on Account'!E:E)), "Found in Alicia API Pull", "MISSING in Alicia's API Pull")) -> Found in Alicia API Pull
A28: 295896210 | B28: 450964503 | C28: State of Utah Aggregate | D28: 346726586 | E28: DNR - OED | F28: http://energy.utah.gov | G28: G-8F73JSYN4N | H28: =IF(G28="", "", IF(ISNUMBER(_xlfn.XMATCH(G28, 'Champions Sheet'!H:H)), "Found in Master", "MISSING in Alicia's")) -> Found in Master | I28: =IF(G28="", "", IF(ISNUMBER(_xlfn.XMATCH(G28, 'State Google Tags on Account'!E:E)), "Found in Alicia API Pull", "MISSING in Alicia's API Pull")) -> Found in Alicia API Pull
A29: 295896210 | B29: 483039742 | C29: DGO - All Websites | D29: 367864194 | E29: DGO - Ethics | F29: http://ethics.utah.gov/ | G29: G-F8VR9SLJYS | H29: =IF(G29="", "", IF(ISNUMBER(_xlfn.XMATCH(G29, 'Champions Sheet'!H:H)), "Found in Master", "MISSING in Alicia's")) -> MISSING in Alicia's | I29: =IF(G29="", "", IF(ISNUMBER(_xlfn.XMATCH(G29, 'State Google Tags on Account'!E:E)), "Found in Alicia API Pull", "MISSING in Alicia's API Pull")) -> Found in Alicia API Pull
A30: 295896210 | B30: 488601532 | C30: State of Utah Aggregate - Low Traffic | D30: 367864194 | E30: DGO - Ethics | F30: http://ethics.utah.gov/ | G30: G-F8VR9SLJYS | H30: =IF(G30="", "", IF(ISNUMBER(_xlfn.XMATCH(G30, 'Champions Sheet'!H:H)), "Found in Master", "MISSING in Alicia's")) -> MISSING in Alicia's | I30: =IF(G30="", "", IF(ISNUMBER(_xlfn.XMATCH(G30, 'State Google Tags on Account'!E:E)), "Found in Alicia API Pull", "MISSING in Alicia's API Pull")) -> Found in Alicia API Pull
A31: 295896210 | B31: 482352716 | C31: DHHS - Roll-up - All properties | D31: 346731853 | E31: DHHS - JJYS - jjys.utah.gov | F31: http://jjys.utah.gov | G31: G-XC34LG48EN | H31: =IF(G31="", "", IF(ISNUMBER(_xlfn.XMATCH(G31, 'Champions Sheet'!H:H)), "Found in Master", "MISSING in Alicia's")) -> MISSING in Alicia's | I31: =IF(G31="", "", IF(ISNUMBER(_xlfn.XMATCH(G31, 'State Google Tags on Account'!E:E)), "Found in Alicia API Pull", "MISSING in Alicia's API Pull")) -> Found in Alicia API Pull
A32: 295896210 | B32: 450964503 | C32: State of Utah Aggregate | D32: 346731853 | E32: DHHS - JJYS - jjys.utah.gov | F32: http://jjys.utah.gov | G32: G-XC34LG48EN | H32: =IF(G32="", "", IF(ISNUMBER(_xlfn.XMATCH(G32, 'Champions Sheet'!H:H)), "Found in Master", "MISSING in Alicia's")) -> MISSING in Alicia's | I32: =IF(G32="", "", IF(ISNUMBER(_xlfn.XMATCH(G32, 'State Google Tags on Account'!E:E)), "Found in Alicia API Pull", "MISSING in Alicia's API Pull")) -> Found in Alicia API Pull
A33: 295896210 | B33: 488601532 | C33: State of Utah Aggregate - Low Traffic | D33: 385235281 | E33: CCJJ - Judicial Vacancy | F33: http://judicialvacancy.utah.gov/ | G33: G-PCZY0K8JQG | H33: =IF(G33="", "", IF(ISNUMBER(_xlfn.XMATCH(G33, 'Champions Sheet'!H:H)), "Found in Master", "MISSING in Alicia's")) -> MISSING in Alicia's | I33: =IF(G33="", "", IF(ISNUMBER(_xlfn.XMATCH(G33, 'State Google Tags on Account'!E:E)), "Found in Alicia API Pull", "MISSING in Alicia's API Pull")) -> Found in Alicia API Pull
... A202: 295896210 | B202: 450964503 | C202: State of Utah Aggregate | D202: 433435376 | E202: DGO - DHRM - Gateway | F202: https://gateway.utah.gov | G202: G-5S6VBKNTH9 | H202: =IF(G202="", "", IF(ISNUMBER(_xlfn.XMATCH(G202, 'Champions Sheet'!H:H)), "Found in Master", "MISSING in Alicia's")) -> MISSING in Alicia's | I202: =IF(G202="", "", IF(ISNUMBER(_xlfn.XMATCH(G202, 'State Google Tags on Account'!E:E)), "Found in Alicia API Pull", "MISSING in Alicia's API Pull")) -> Found in Alicia API Pull
A203: 295896210 | B203: 482151148 | C203: DNR - All Websites | D203: 370585777 | E203: DNR - UGS | F203: https://geology.utah.gov, https://geology.utah.gov | G203: G-983EZBYB1K, G-EN4LC4Q69P | H203: =IF(G203="", "", IF(ISNUMBER(_xlfn.XMATCH(G203, 'Champions Sheet'!H:H)), "Found in Master", "MISSING in Alicia's")) -> MISSING in Alicia's | I203: Manually only found G-EN4LC4Q69P
A204: 295896210 | B204: 450964503 | C204: State of Utah Aggregate | D204: 370585777 | E204: DNR - UGS | F204: https://geology.utah.gov, https://geology.utah.gov | G204: G-983EZBYB1K, G-EN4LC4Q69P | H204: =IF(G204="", "", IF(ISNUMBER(_xlfn.XMATCH(G204, 'Champions Sheet'!H:H)), "Found in Master", "MISSING in Alicia's")) -> MISSING in Alicia's | I204: =IF(G204="", "", IF(ISNUMBER(_xlfn.XMATCH(G204, 'State Google Tags on Account'!E:E)), "Found in Alicia API Pull", "MISSING in Alicia's API Pull")) -> MISSING in Alicia's API Pull
A205: 295896210 | B205: 450964503 | C205: State of Utah Aggregate | D205: 365089704 | E205: GOPB - Main Website | F205: https://gomb.utah.gov | G205: G-DZYWHQZP43 | H205: =IF(G205="", "", IF(ISNUMBER(_xlfn.XMATCH(G205, 'Champions Sheet'!H:H)), "Found in Master", "MISSING in Alicia's")) -> MISSING in Alicia's | I205: =IF(G205="", "", IF(ISNUMBER(_xlfn.XMATCH(G205, 'State Google Tags on Account'!E:E)), "Found in Alicia API Pull", "MISSING in Alicia's API Pull")) -> Found in Alicia API Pull
A206: 295896210 | B206: 450964503 | C206: State of Utah Aggregate | D206: 468255943 | E206: GOV - Governor's Office | F206: https://governor.utah.gov | G206: G-4FL295WNP8 | H206: =IF(G206="", "", IF(ISNUMBER(_xlfn.XMATCH(G206, 'Champions Sheet'!H:H)), "Found in Master", "MISSING in Alicia's")) -> MISSING in Alicia's | I206: =IF(G206="", "", IF(ISNUMBER(_xlfn.XMATCH(G206, 'State Google Tags on Account'!E:E)), "Found in Alicia API Pull", "MISSING in Alicia's API Pull")) -> Found in Alicia API Pull
A207: 295896210 | B207: 483039742 | C207: DGO - All Websites | D207: 433479223 | E207: DGO - Main Website | F207: https://govops.utah.gov | G207: G-G8NLKD6M0E | H207: =IF(G207="", "", IF(ISNUMBER(_xlfn.XMATCH(G207, 'Champions Sheet'!H:H)), "Found in Master", "MISSING in Alicia's")) -> MISSING in Alicia's | I207: =IF(G207="", "", IF(ISNUMBER(_xlfn.XMATCH(G207, 'State Google Tags on Account'!E:E)), "Found in Alicia API Pull", "MISSING in Alicia's API Pull")) -> Found in Alicia API Pull
A208: 295896210 | B208: 450964503 | C208: State of Utah Aggregate | D208: 433479223 | E208: DGO - Main Website | F208: https://govops.utah.gov | G208: G-G8NLKD6M0E | H208: =IF(G208="", "", IF(ISNUMBER(_xlfn.XMATCH(G208, 'Champions Sheet'!H:H)), "Found in Master", "MISSING in Alicia's")) -> MISSING in Alicia's | I208: =IF(G208="", "", IF(ISNUMBER(_xlfn.XMATCH(G208, 'State Google Tags on Account'!E:E)), "Found in Alicia API Pull", "MISSING in Alicia's API Pull")) -> Found in Alicia API Pull
A209: 295896210 | B209: 482352716 | C209: DHHS - Roll-up - All properties | D209: 487354183 | E209: DHHS - Gray Matters - graymatters.utah.gov | F209: https://graymatters.utah.gov | G209: G-D9P8778J31 | H209: =IF(G209="", "", IF(ISNUMBER(_xlfn.XMATCH(G209, 'Champions Sheet'!H:H)), "Found in Master", "MISSING in Alicia's")) -> MISSING in Alicia's | I209: =IF(G209="", "", IF(ISNUMBER(_xlfn.XMATCH(G209, 'State Google Tags on Account'!E:E)), "Found in Alicia API Pull", "MISSING in Alicia's API Pull")) -> Found in Alicia API Pull
A210: 295896210 | B210: 450964503 | C210: State of Utah Aggregate | D210: 487354183 | E210: DHHS - Gray Matters - graymatters.utah.gov | F210: https://graymatters.utah.gov | G210: G-D9P8778J31 | H210: =IF(G210="", "", IF(ISNUMBER(_xlfn.XMATCH(G210, 'Champions Sheet'!H:H)), "Found in Master", "MISSING in Alicia's")) -> MISSING in Alicia's | I210: =IF(G210="", "", IF(ISNUMBER(_xlfn.XMATCH(G210, 'State Google Tags on Account'!E:E)), "Found in Alicia API Pull", "MISSING in Alicia's API Pull")) -> Found in Alicia API Pull
A211: 295896210 | B211: 482151148 | C211: DNR - All Websites | D211: 335396203 | E211: DNR - greatsaltlake.utah.gov | F211: https://greatsaltlake.utah.gov | G211: G-MZ312296YY | H211: =IF(G211="", "", IF(ISNUMBER(_xlfn.XMATCH(G211, 'Champions Sheet'!H:H)), "Found in Master", "MISSING in Alicia's")) -> MISSING in Alicia's | I211: =IF(G211="", "", IF(ISNUMBER(_xlfn.XMATCH(G211, 'State Google Tags on Account'!E:E)), "Found in Alicia API Pull", "MISSING in Alicia's API Pull")) -> Found in Alicia API Pull
A212: 295896210 | B212: 450964503 | C212: State of Utah Aggregate | D212: 335396203 | E212: DNR - greatsaltlake.utah.gov | F212: https://greatsaltlake.utah.gov | G212: G-MZ312296YY | H212: =IF(G212="", "", IF(ISNUMBER(_xlfn.XMATCH(G212, 'Champions Sheet'!H:H)), "Found in Master", "MISSING in Alicia's")) -> MISSING in Alicia's | I212: =IF(G212="", "", IF(ISNUMBER(_xlfn.XMATCH(G212, 'State Google Tags on Account'!E:E)), "Found in Alicia API Pull", "MISSING in Alicia's API Pull")) -> Found in Alicia API Pull
A213: 295896210 | B213: 450964503 | C213: State of Utah Aggregate | D213: 461167456 | E213: UNG - Main Website | F213: https://guard.utah.gov | G213: G-RM6WCDG2H3 | H213: =IF(G213="", "", IF(ISNUMBER(_xlfn.XMATCH(G213, 'Champions Sheet'!H:H)), "Found in Master", "MISSING in Alicia's")) -> Found in Master | I213: =IF(G213="", "", IF(ISNUMBER(_xlfn.XMATCH(G213, 'State Google Tags on Account'!E:E)), "Found in Alicia API Pull", "MISSING in Alicia's API Pull")) -> Found in Alicia API Pull
...

Sheet Master Sheet
A1: Agency | B1: Original Data Collection | C1: Website_Title | D1: Host Name | E1: URL Path | F1: Status | G1: GTM | H1: G-Tag | I1: State of Utah GA Account Y/N | J1: GA property Name | K1: Missing?
A2: BOPP | B2: bop.utah.gov | C2: Board of Pardons & Parole | D2: bop.utah.gov | E2: https://bop.utah.gov | F2: Active (200) | G2: GTM-T34QF72M | H2: G-4VZFST59D0 | I2: Yes | J2: BOPP - Main Website | K2: Found in Rollup
A3: CCE | B3: pulled from google analytics | C3: N/A | D3: history.utah.gov | E3: https://history.utah.gov | F3: Active | G3: N/A | H3: G-TRQWCP98L2 | I3: Yes | J3: CCE - HS | K3: Taken from Rollup
A4: CCE | B4: https://artsandmuseums.utah.gov/ | C4: Utah Division of Arts & Museums | A Division of the Department of Cultural & Community Engagement | D4: artsandmuseums.utah.gov | E4: https://artsandmuseums.utah.gov/ | F4: Active (200) | G4: None Found | H4: G-76RDJXHW4B | I4: Yes | J4: CCE - AM | K4: Found in Rollup
A5: CCE | B5: pulled from google analytics | C5: N/A | D5: museumsocialimpact.org | E5: https://museumsocialimpact.org | F5: Active | G5: N/A | H5: G-4ERD645EY8 | I5: Yes | J5: CCE - AM - Museum Social Impact | K5: Taken from Rollup
A6: CCE | B6: pulled from google analytics | C6: N/A | D6: america250.utah.gov | E6: https://america250.utah.gov | F6: Active | G6: N/A | H6: G-104CMG7MZ8 | I6: Yes | J6: CCE - America 250 | K6: Taken from Rollup
A7: CCE | B7: pulled from google analytics | C7: N/A | D7: flag.utah.gov | E7: https://flag.utah.gov | F7: Active | G7: N/A | H7: G-TJYRDR531R | I7: Yes | J7: CCE - Flag | K7: Taken from Rollup
A8: CCE | B8: pulled from google analytics | C8: N/A | D8: historytogo.utah.gov | E8: https://historytogo.utah.gov | F8: Active | G8: N/A | H8: G-1Z3CWEGE6D | I8: Yes | J8: CCE - HS - History To Go | K8: Taken from Rollup
A9: CCE | B9: pulled from google analytics | C9: N/A | D9: ilovehistory.utah.gov | E9: https://ilovehistory.utah.gov | F9: Active | G9: N/A | H9: G-TMNJHE73N5 | I9: Yes | J9: CCE - HS - ILoveHistory | K9: Taken from Rollup
A10: CCE | B10: https://indian.utah.gov/ | C10: Utah Division of Indian Affairs | A Division of the Department of Cultural & Community Engagement | D10: indian.utah.gov | E10: https://indian.utah.gov/ | F10: Active (200) | G10: None Found | H10: G-L41CPHPD25 | I10: Yes | J10: CCE - IA | K10: Found in Rollup
A11: CCE | B11: pulled from google analytics | C11: N/A | D11: cceintranet.utah.gov | E11: https://cceintranet.utah.gov | F11: Active | G11: N/A | H11: G-6HVSGMMQCC | I11: Yes | J11: CCE - Intranet | K11: Taken from Rollup
A12: CCE | B12: https://multicultural.utah.gov/ | C12: Utah Division Of Multicultural Affairs | A Division of the Utah Department of Cultural and Community Engagement | D12: multicultural.utah.gov | E12: https://multicultural.utah.gov/ | F12: Active (200) | G12: None Found | H12: G-BGQYP4L42X | I12: Yes | J12: CCE - MA | K12: Found in Rollup
... A31: CCJJ | B31: https://justice.utah.gov/ | C31: Department of Criminal Justice | D31: justice.utah.gov | E31: https://justice.utah.gov/ | F31: Active (200) | G31: None Found | H31: G-9SLZ0P2YXT | I31: Yes | J31: CCJJ - Main Website | K31: Found in Rollup
A32: CCJJ | B32: https://justice.utah.gov/about-2/ | D32: justice.utah.gov | E32: https://justice.utah.gov/about-2/ | F32: Error (404) | G32: HTTP 404 | H32: G-9SLZ0P2YXT | I32: Yes | J32: CCJJ - Main Website | K32: Found in Rollup
A33: CCJJ | B33: https://justice.utah.gov/about-ccjj/extraditions/ | C33: Extraditions | Department of Criminal Justice | D33: justice.utah.gov | E33: https://justice.utah.gov/about-ccjj/extraditions/ | F33: Active (200) | G33: None Found | H33: G-9SLZ0P2YXT | I33: Yes | J33: CCJJ - Main Website | K33: Found in Rollup
A34: CCJJ | B34: https://justice.utah.gov/about-ccjj/judicial-nominating-commission/ | C34: Judicial Nominating Commission | Department of Criminal Justice | D34: justice.utah.gov | E34: https://justice.utah.gov/about-ccjj/judicial-nominating-commission/ | F34: Active (200) | G34: None Found | H34: G-9SLZ0P2YXT | I34: Yes | J34: CCJJ - Main Website | K34: Found in Rollup
A35: CCJJ | B35: https://justice.utah.gov/grants/ | C35: Grants | Department of Criminal Justice | D35: justice.utah.gov | E35: https://justice.utah.gov/grants/ | F35: Active (200) | G35: None Found | H35: G-9SLZ0P2YXT | I35: Yes | J35: CCJJ - Main Website | K35: Found in Rollup
A36: CCJJ | B36: https://justice.utah.gov/grants/federal-funding/ | C36: Federal Funding | Department of Criminal Justice | D36: justice.utah.gov | E36: https://justice.utah.gov/grants/federal-funding/ | F36: Active (200) | G36: None Found | H36: G-9SLZ0P2YXT | I36: Yes | J36: CCJJ - Main Website | K36: Found in Rollup
A37: CCJJ | B37: https://justice.utah.gov/grants/state-funding/ | C37: State Funding | Department of Criminal Justice | D37: justice.utah.gov | E37: https://justice.utah.gov/grants/state-funding/ | F37: Active (200) | G37: None Found | H37: G-9SLZ0P2YXT | I37: Yes | J37: CCJJ - Main Website | K37: Found in Rollup
A38: CCJJ | B38: https://justice.utah.gov/juvenile-justice/ | D38: justice.utah.gov | E38: https://justice.utah.gov/juvenile-justice/ | F38: Error (404) | G38: HTTP 404 | H38: G-9SLZ0P2YXT | I38: Yes | J38: CCJJ - Main Website | K38: Found in Rollup
A39: CCJJ | B39: https://justice.utah.gov/research-and-reports/ | D39: justice.utah.gov | E39: https://justice.utah.gov/research-and-reports/ | F39: Error (404) | G39: HTTP 404 | H39: G-9SLZ0P2YXT | I39: Yes | J39: CCJJ - Main Website | K39: Found in Rollup
A40: CCJJ | B40: https://justice.utah.gov/sentencing/ | D40: justice.utah.gov | E40: https://justice.utah.gov/sentencing/ | F40: Error (404) | G40: HTTP 404 | H40: G-9SLZ0P2YXT | I40: Yes | J40: CCJJ - Main Website | K40: Found in Rollup
A41: CCJJ | B41: https://justice.utah.gov/sentencing/eforms/ | C41: eForms | Department of Criminal Justice | D41: justice.utah.gov | E41: https://justice.utah.gov/sentencing/eforms/ | F41: Active (200) | G41: None Found | H41: G-9SLZ0P2YXT | I41: Yes | J41: CCJJ - Main Website | K41: Found in Rollup
A42: CCJJ | B42: https://justice.utah.gov/sentencing/sentencing-and-release-guidelines/ | D42: justice.utah.gov | E42: https://justice.utah.gov/sentencing/sentencing-and-release-guidelines/ | F42: Error (404) | G42: HTTP 404 | H42: G-9SLZ0P2YXT | I42: Yes | J42: CCJJ - Main Website | K42: Found in Rollup
A43: CCJJ | B43: https://crimevictim.utah.gov/grants/grant-solicitations/ | D43: crimevictim.utah.gov | E43: https://crimevictim.utah.gov/grants/grant-solicitations/ | F43: Error (404) | G43: HTTP 404 | H43: G-2NQRP84TH7 | I43: Yes | J43: CCJJ - UOVC | K43: Found in Rollup
A44: CCJJ | B44: https://crimevictim.utah.gov/victim-financial-assistance/application-process/ | D44: crimevictim.utah.gov | E44: https://crimevictim.utah.gov/victim-financial-assistance/application-process/ | F44: Error (404) | G44: HTTP 404 | H44: G-2NQRP84TH7 | I44: Yes | J44: CCJJ - UOVC | K44: Found in Rollup
A45: CCJJ | B45: https://crimevictim.utah.gov/victim-rights/ | D45: crimevictim.utah.gov | E45: https://crimevictim.utah.gov/victim-rights/ | F45: Error (404) | G45: HTTP 404 | H45: G-2NQRP84TH7 | I45: Yes | J45: CCJJ - UOVC | K45: Found in Rollup
A46: DABS | B46: parentsempowered.org | C46: Parents Empowered | D46: parentsempowered.org | E46: https://parentsempowered.org | F46: Active (200) | G46: GTM-53KZVQ | H46: G-3PPNCS7EKQ | I46: No | J46: Tag Firing but Not Found in State Analytics | K46: MISSING in Rollup
A47: CPB | B47: pulled from google analytics | C47: N/A | D47: utahstatecapitol.utah.gov | E47: https://utahstatecapitol.utah.gov | F47: Active | G47: N/A | H47: G-0TCMJHG46L | I47: Yes | J47: CPB - Utah State Capitol | K47: Taken from Rollup
A48: CSRO | B48: pulled from google analytics | C48: N/A | D48: csro.utah.gov | E48: https://csro.utah.gov | F48: Active | G48: N/A | H48: G-RWZKPNR2NS | I48: Yes | J48: CSRO - Career Service Review Office | K48: Taken from Rollup
A49: DABS | B49: abs.utah.gov | C49: Utah DABS - Utah DABS | D49: abs.utah.gov | E49: https://abs.utah.gov | F49: Active (200) | G49: GTM-5DQJR6SM | H49: G-X5QN659TK4 | I49: Yes | J49: DABS - Main Website | K49: Found in Rollup
A50: DABS | B50: Licensee Ordering Portal | C50: Licensee Ordering Portal | D50: abs.utah.gov | E50: https://abs.utah.gov/licenses-permits/licensee-orders/ | F50: No Original Link | G50: GTM-5DQJR6SM | H50: G-X5QN659TK4 | I50: Yes | J50: DABS - Main Website | K50: Found in Rollup
A51: DABS | B51: Licensing and Permitting System | C51: Licensing and Permitting System | D51: abs.utah.gov | E51: https://abs.utah.gov/licenses-permits/licensing-system/ | F51: No Original Link | G51: GTM-5DQJR6SM | H51: G-X5QN659TK4 | I51: Yes | J51: DABS - Main Website | K51: Found in Rollup
A52: DABS | B52: Learning Portal (SABA) | C52: Learning Portal (SABA) | D52: abs.utah.gov | E52: https://abs.utah.gov/licenses-permits/training/ | F52: No Original Link | G52: GTM-5DQJR6SM | H52: G-X5QN659TK4 | I52: Yes | J52: DABS - Main Website | K52: Found in Rollup
A53: DABS | B53: Special Ordering Portal | C53: Special Ordering Portal | D53: abs.utah.gov | E53: https://abs.utah.gov/shop-products/special-orders/ | F53: No Original Link | G53: GTM-5DQJR6SM | H53: G-X5QN659TK4 | I53: Yes | J53: DABS - Main Website | K53: Found in Rollup
A54: DABS | B54: Vendor Portal | C54: Vendor Portal | D54: abs.utah.gov | E54: https://abs.utah.gov/vendors/vendor-portal/ | F54: No Original Link | G54: GTM-5DQJR6SM | H54: G-X5QN659TK4 | I54: Yes | J54: DABS - Main Website | K54: Found in Rollup
A55: DABS | B55: Product Locator | C55: Product Locator | D55: webapps2.abc.utah.gov | E55: https://webapps2.abc.utah.gov/ProdApps/ProductLocatorCore | F55: No Original Link | G55: None Found | H55: G-X5QN659TK4 | I55: Yes | J55: DABS - Main Website | K55: Found in Rollup
A56: DABS | B56: Rare and High Demand Products Portal | C56: Rare and High Demand Products Portal | D56: webapps2.abc.utah.gov | E56: https://webapps2.abc.utah.gov/ProdApps/RareHighDemandProducts | F56: No Original Link | G56: None Found | H56: G-X5QN659TK4 | I56: Yes | J56: DABS - Main Website | K56: Found in Rollup
A57: DPS | B57: https://publicsafetyutah.govqa.us/WEBAPP/_rs/(S(zfixk5ebkudzdn0wyzgrv2jk))/SupportHome.aspx?&lp=9 | C57: Utah Department of Public Safety | Records Center | D57: publicsafetyutah.govqa.us | E57: https://publicsafetyutah.govqa.us/WEBAPP/_rs/(S(zfixk5ebkudzdn0wyzgrv2jk))/SupportHome.aspx?&lp=9 | F57: Active (200) | G57: None Found | H57: G-4SLB68RYEV, UA-113043676-70 | I57: No | J57: Tag Firing but Not Found in State Analytics | K57: MISSING in Rollup
... A133: DWS | B133: jobs.utah.gov/jobseeker | C133: Job Seekers | D133: jobs.utah.gov | E133: https://jobs.utah.gov/jobseeker | F133: Active (200) | G133: GTM-PL8ZV9W | H133: G-DYDNPQ9XL9 | I133: No | J133: Tag Firing but Not Found in State Analytics | K133: MISSING in Rollup
...
